<?xml version="1.0" encoding="utf-8"?>
<!-- This URDF was automatically created by SolidWorks to URDF Exporter! Originally created by Stephen Brawner (brawner@gmail.com) 
     Commit Version: 1.5.1-0-g916b5db  Build Version: 1.5.7152.31018
     For more information, please see http://wiki.ros.org/sw_urdf_exporter -->
<robot
  name="smart_scaffolding">
  <link
    name="base_link">
    <inertial>
      <origin
        xyz="-0.00167670814824843 -0.00124913688864695 0.064051820417217"
        rpy="0 0 0" />
      <mass
        value="0.106288836388757" />
      <inertia
        ixx="3.790587396713E-05"
        ixy="9.22309781853357E-07"
        ixz="1.67520759799362E-06"
        iyy="4.37509049186189E-05"
        iyz="1.20055006036103E-06"
        izz="2.53300051017029E-05" />
    </inertial>
    <visual>
      <origin
        xyz="0 0 0"
        rpy="0 0 0" />
      <geometry>
        <mesh
          filename="package://First_Iteration_Assem/meshes/base_link.STL" />
      </geometry>
      <material
        name="">
        <color
          rgba="0.792156862745098 0.819607843137255 0.933333333333333 1" />
      </material>
    </visual>
    <collision>
      <origin
        xyz="0 0 0"
        rpy="0 0 0" />
      <geometry>
        <mesh
          filename="package://First_Iteration_Assem/meshes/base_link.STL" />
      </geometry>
    </collision>
  </link>
  <link
    name="link_1">
    <inertial>
      <origin
        xyz="0.00329739815166044 -0.00108860830320483 -0.102287417098408"
        rpy="0 0 0" />
      <mass
        value="0.121962443659576" />
      <inertia
        ixx="5.58178420757154E-05"
        ixy="-9.22310577841897E-07"
        ixz="5.4022372955156E-07"
        iyy="7.68589276177781E-05"
        iyz="-1.20055002941655E-06"
        izz="3.80222625240213E-05" />
    </inertial>
    <visual>
      <origin
        xyz="0 0 0"
        rpy="0 0 0" />
      <geometry>
        <mesh
          filename="package://First_Iteration_Assem/meshes/link_1.STL" />
      </geometry>
      <material
        name="">
        <color
          rgba="0.792156862745098 0.819607843137255 0.933333333333333 1" />
      </material>
    </visual>
    <collision>
      <origin
        xyz="0 0 0"
        rpy="0 0 0" />
      <geometry>
        <mesh
          filename="package://First_Iteration_Assem/meshes/link_1.STL" />
      </geometry>
    </collision>
  </link>
  <joint
    name="joint_1"
    type="continuous">
    <origin
      xyz="0 -0.10478 -0.0002"
      rpy="2.3309 0 3.1416" />
    <parent
      link="base_link" />
    <child
      link="link_1" />
    <axis
      xyz="-1 0 0" />
  </joint>
  <link
    name="link_2">
    <inertial>
      <origin
        xyz="0.0264753506561459 0.0139113916966098 -0.117287417095412"
        rpy="0 0 0" />
      <mass
        value="0.121962443652196" />
      <inertia
        ixx="5.58178420730298E-05"
        ixy="-9.22310577651571E-07"
        ixz="5.40223726957375E-07"
        iyy="7.68589276142313E-05"
        iyz="-1.20055002970277E-06"
        izz="3.80222625225677E-05" />
    </inertial>
    <visual>
      <origin
        xyz="0 0 0"
        rpy="0 0 0" />
      <geometry>
        <mesh
          filename="package://First_Iteration_Assem/meshes/link_2.STL" />
      </geometry>
      <material
        name="">
        <color
          rgba="0.792156862745098 0.819607843137255 0.933333333333333 1" />
      </material>
    </visual>
    <collision>
      <origin
        xyz="0 0 0"
        rpy="0 0 0" />
      <geometry>
        <mesh
          filename="package://First_Iteration_Assem/meshes/link_2.STL" />
      </geometry>
    </collision>
  </link>
  <joint
    name="joint_2"
    type="continuous">
    <origin
      xyz="-0.02165 -0.014921 -0.17859"
      rpy="1.5892 0 0" />
    <parent
      link="link_1" />
    <child
      link="link_2" />
    <axis
      xyz="-1 0 0" />
  </joint>
  <link
    name="link_3">
    <inertial>
      <origin
        xyz="0.000881125443796591 0.0443438314640521 -1.94289029309402E-15"
        rpy="0 0 0" />
      <mass
        value="0.0742125648272151" />
      <inertia
        ixx="2.72135201538739E-05"
        ixy="-1.13499847698934E-06"
        ixz="-6.35192694236914E-20"
        iyy="3.21039471722149E-05"
        iyz="-2.37439894783956E-21"
        izz="4.24100906081661E-05" />
    </inertial>
    <visual>
      <origin
        xyz="0 0 0"
        rpy="0 0 0" />
      <geometry>
        <mesh
          filename="package://First_Iteration_Assem/meshes/link_3.STL" />
      </geometry>
      <material
        name="">
        <color
          rgba="0.792156862745098 0.819607843137255 0.933333333333333 1" />
      </material>
    </visual>
    <collision>
      <origin
        xyz="0 0 0"
        rpy="0 0 0" />
      <geometry>
        <mesh
          filename="package://First_Iteration_Assem/meshes/link_3.STL" />
      </geometry>
    </collision>
  </link>
  <joint
    name="joint_3"
    type="continuous">
    <origin
      xyz="0.02595 0.086907 -0.24944"
      rpy="2.3631 0 0" />
    <parent
      link="link_2" />
    <child
      link="link_3" />
    <axis
      xyz="-1 0 0" />
  </joint>

<transmission name="t_joint_1">
    <type>transmission_interface/SimpleTransmission</type>
    <joint name="joint_1">
      <hardwareInterface>EffortJointInterface</hardwareInterface>
    </joint>
    <actuator name="m_joint_1">
      <hardwareInterface>EffortJointInterface</hardwareInterface>
      <mechanicalReduction>1</mechanicalReduction>
    </actuator>
</transmission>
<transmission name="t_joint_2">
    <type>transmission_interface/SimpleTransmission</type>
    <joint name="joint_2">
      <hardwareInterface>EffortJointInterface</hardwareInterface>
    </joint>
    <actuator name="m_joint_2">
      <hardwareInterface>EffortJointInterface</hardwareInterface>
      <mechanicalReduction>1</mechanicalReduction>
    </actuator>
</transmission>
<transmission name="t_joint_3">
    <type>transmission_interface/SimpleTransmission</type>
    <joint name="joint_3">
      <hardwareInterface>EffortJointInterface</hardwareInterface>
    </joint>
    <actuator name="m_joint_3">
      <hardwareInterface>EffortJointInterface</hardwareInterface>
      <mechanicalReduction>1</mechanicalReduction>
    </actuator>
</transmission>
  <gazebo>
  <plugin name="gazebo_ros_control" filename="libgazebo_ros_control.so">
    <robotNamespace>/smart_scaffolding</robotNamespace>
    <legacyModeNS>true</legacyModeNS>
  </plugin>
</gazebo>
</robot>
